Downloading shards:   0%|          | 0/2 [00:00<?, ?it/s]Downloading shards:  50%|█████     | 1/2 [16:56<16:56, 1016.23s/it]Error while downloading from https://cdn-lfs-us-1.hf.co/repos/e4/5a/e45a14e07b22b4350ac8a49a28975e1003fc0cf125bd48861865ec4b58441dcf/1780a9502f56f592cb4d6262c8c76ca8ad36a86b0257e052c672d87f49707e80?response-content-disposition=inline%3B+filename*%3DUTF-8%27%27model-00002-of-000002.safetensors%3B+filename%3D%22model-00002-of-000002.safetensors%22%3B&Expires=1745309883&Policy=eyJTdGF0ZW1lbnQiOlt7IkNvbmRpdGlvbiI6eyJEYXRlTGVzc1RoYW4iOnsiQVdTOkVwb2NoVGltZSI6MTc0NTMwOTg4M319LCJSZXNvdXJjZSI6Imh0dHBzOi8vY2RuLWxmcy11cy0xLmhmLmNvL3JlcG9zL2U0LzVhL2U0NWExNGUwN2IyMmI0MzUwYWM4YTQ5YTI4OTc1ZTEwMDNmYzBjZjEyNWJkNDg4NjE4NjVlYzRiNTg0NDFkY2YvMTc4MGE5NTAyZjU2ZjU5MmNiNGQ2MjYyYzhjNzZjYThhZDM2YTg2YjAyNTdlMDUyYzY3MmQ4N2Y0OTcwN2U4MD9yZXNwb25zZS1jb250ZW50LWRpc3Bvc2l0aW9uPSoifV19&Signature=LtB5VXBbC3Mb1DQZ0phQJ95W2Wl8KeIXxGdwhBjnHx8c3Aj3yWJ%7EoJTSQZmdvot6DJdLq9ZX5kEU4n9KaABXr5NAbbc%7EMgRxrv4X5rprS2QlW6HcoQSRmuf6WNoELV2e9ebdKN4yWHq4IMJOObAI5Ksswxw4rS91TnUTVwkP7D3FXCKgEcDiwdvMWE3S7OGhOp09K5h5aa13%7ENN00cjAAhUECijkMIjHapYyjr8qE5NqkYJ6fnWk%7EKE2ahR9cqiPJs3uXPtwMf%7E5VMmtR2Z6Lu6JDETanmvtxdhP45Qq42jQH6-Wt-CpJUVzvgwTBS4mZckAW%7EIj6SBiO1y3PyyyiA__&Key-Pair-Id=K24J24Z295AEI9: HTTPSConnectionPool(host='cdn-lfs-us-1.hf.co', port=443): Read timed out.
Trying to resume download...
Downloading shards:  50%|█████     | 1/2 [30:26<30:26, 1826.51s/it]
Traceback (most recent call last):
  File "/home/bingxing2/ailab/wangkuncan/.conda/envs/setup/lib/python3.10/site-packages/urllib3/response.py", line 754, in _error_catcher
    yield
  File "/home/bingxing2/ailab/wangkuncan/.conda/envs/setup/lib/python3.10/site-packages/urllib3/response.py", line 879, in _raw_read
    data = self._fp_read(amt, read1=read1) if not fp_closed else b""
  File "/home/bingxing2/ailab/wangkuncan/.conda/envs/setup/lib/python3.10/site-packages/urllib3/response.py", line 862, in _fp_read
    return self._fp.read(amt) if amt is not None else self._fp.read()
  File "/home/bingxing2/ailab/wangkuncan/.conda/envs/setup/lib/python3.10/http/client.py", line 464, in read
    s = self.fp.read(amt)
  File "/home/bingxing2/ailab/wangkuncan/.conda/envs/setup/lib/python3.10/socket.py", line 705, in readinto
    return self._sock.recv_into(b)
  File "/home/bingxing2/ailab/wangkuncan/.conda/envs/setup/lib/python3.10/site-packages/urllib3/util/ssltransport.py", line 99, in recv_into
    return self.read(nbytes, buffer)
  File "/home/bingxing2/ailab/wangkuncan/.conda/envs/setup/lib/python3.10/site-packages/urllib3/util/ssltransport.py", line 82, in read
    return self._wrap_ssl_read(len, buffer)
  File "/home/bingxing2/ailab/wangkuncan/.conda/envs/setup/lib/python3.10/site-packages/urllib3/util/ssltransport.py", line 211, in _wrap_ssl_read
    return self._ssl_io_loop(self.sslobj.read, len, buffer)
  File "/home/bingxing2/ailab/wangkuncan/.conda/envs/setup/lib/python3.10/site-packages/urllib3/util/ssltransport.py", line 266, in _ssl_io_loop
    buf = self.socket.recv(SSL_BLOCKSIZE)
  File "/home/bingxing2/ailab/wangkuncan/.conda/envs/setup/lib/python3.10/ssl.py", line 1258, in recv
    return self.read(buflen)
  File "/home/bingxing2/ailab/wangkuncan/.conda/envs/setup/lib/python3.10/ssl.py", line 1131, in read
    return self._sslobj.read(len)
TimeoutError: The read operation timed out

The above exception was the direct cause of the following exception:

Traceback (most recent call last):
  File "/home/bingxing2/ailab/wangkuncan/.local/lib/python3.10/site-packages/requests/models.py", line 820, in generate
    yield from self.raw.stream(chunk_size, decode_content=True)
  File "/home/bingxing2/ailab/wangkuncan/.conda/envs/setup/lib/python3.10/site-packages/urllib3/response.py", line 1066, in stream
    data = self.read(amt=amt, decode_content=decode_content)
  File "/home/bingxing2/ailab/wangkuncan/.conda/envs/setup/lib/python3.10/site-packages/urllib3/response.py", line 955, in read
    data = self._raw_read(amt)
  File "/home/bingxing2/ailab/wangkuncan/.conda/envs/setup/lib/python3.10/site-packages/urllib3/response.py", line 878, in _raw_read
    with self._error_catcher():
  File "/home/bingxing2/ailab/wangkuncan/.conda/envs/setup/lib/python3.10/contextlib.py", line 153, in __exit__
    self.gen.throw(typ, value, traceback)
  File "/home/bingxing2/ailab/wangkuncan/.conda/envs/setup/lib/python3.10/site-packages/urllib3/response.py", line 759, in _error_catcher
    raise ReadTimeoutError(self._pool, None, "Read timed out.") from e  # type: ignore[arg-type]
urllib3.exceptions.ReadTimeoutError: HTTPSConnectionPool(host='cdn-lfs-us-1.hf.co', port=443): Read timed out.

During handling of the above exception, another exception occurred:

Traceback (most recent call last):
  File "/home/bingxing2/ailab/wangkuncan/.local/lib/python3.10/site-packages/huggingface_hub/file_download.py", line 449, in http_get
    for chunk in r.iter_content(chunk_size=constants.DOWNLOAD_CHUNK_SIZE):
  File "/home/bingxing2/ailab/wangkuncan/.local/lib/python3.10/site-packages/requests/models.py", line 826, in generate
    raise ConnectionError(e)
requests.exceptions.ConnectionError: HTTPSConnectionPool(host='cdn-lfs-us-1.hf.co', port=443): Read timed out.

During handling of the above exception, another exception occurred:

Traceback (most recent call last):
  File "/home/bingxing2/ailab/wangkuncan/.conda/envs/setup/lib/python3.10/site-packages/urllib3/connectionpool.py", line 773, in urlopen
    self._prepare_proxy(conn)
  File "/home/bingxing2/ailab/wangkuncan/.conda/envs/setup/lib/python3.10/site-packages/urllib3/connectionpool.py", line 1042, in _prepare_proxy
    conn.connect()
  File "/home/bingxing2/ailab/wangkuncan/.conda/envs/setup/lib/python3.10/site-packages/urllib3/connection.py", line 713, in connect
    self.sock = sock = self._connect_tls_proxy(self.host, sock)
  File "/home/bingxing2/ailab/wangkuncan/.conda/envs/setup/lib/python3.10/site-packages/urllib3/connection.py", line 813, in _connect_tls_proxy
    sock_and_verified = _ssl_wrap_socket_and_match_hostname(
  File "/home/bingxing2/ailab/wangkuncan/.conda/envs/setup/lib/python3.10/site-packages/urllib3/connection.py", line 920, in _ssl_wrap_socket_and_match_hostname
    ssl_sock = ssl_wrap_socket(
  File "/home/bingxing2/ailab/wangkuncan/.conda/envs/setup/lib/python3.10/site-packages/urllib3/util/ssl_.py", line 460, in ssl_wrap_socket
    ssl_sock = _ssl_wrap_socket_impl(sock, context, tls_in_tls, server_hostname)
  File "/home/bingxing2/ailab/wangkuncan/.conda/envs/setup/lib/python3.10/site-packages/urllib3/util/ssl_.py", line 504, in _ssl_wrap_socket_impl
    return ssl_context.wrap_socket(sock, server_hostname=server_hostname)
  File "/home/bingxing2/ailab/wangkuncan/.conda/envs/setup/lib/python3.10/ssl.py", line 512, in wrap_socket
    return self.sslsocket_class._create(
  File "/home/bingxing2/ailab/wangkuncan/.conda/envs/setup/lib/python3.10/ssl.py", line 1070, in _create
    self.do_handshake()
  File "/home/bingxing2/ailab/wangkuncan/.conda/envs/setup/lib/python3.10/ssl.py", line 1341, in do_handshake
    self._sslobj.do_handshake()
TimeoutError: _ssl.c:980: The handshake operation timed out

The above exception was the direct cause of the following exception:

Traceback (most recent call last):
  File "/home/bingxing2/ailab/wangkuncan/.conda/envs/setup/lib/python3.10/site-packages/urllib3/connectionpool.py", line 775, in urlopen
    self._raise_timeout(
  File "/home/bingxing2/ailab/wangkuncan/.conda/envs/setup/lib/python3.10/site-packages/urllib3/connectionpool.py", line 367, in _raise_timeout
    raise ReadTimeoutError(
urllib3.exceptions.ReadTimeoutError: HTTPSConnectionPool(host='cdn-lfs-us-1.hf.co', port=443): Read timed out. (read timeout=10)

The above exception was the direct cause of the following exception:

urllib3.exceptions.ProxyError: ('Unable to connect to proxy', ReadTimeoutError("HTTPSConnectionPool(host='cdn-lfs-us-1.hf.co', port=443): Read timed out. (read timeout=10)"))

The above exception was the direct cause of the following exception:

Traceback (most recent call last):
  File "/home/bingxing2/ailab/wangkuncan/.local/lib/python3.10/site-packages/requests/adapters.py", line 667, in send
    resp = conn.urlopen(
  File "/home/bingxing2/ailab/wangkuncan/.conda/envs/setup/lib/python3.10/site-packages/urllib3/connectionpool.py", line 841, in urlopen
    retries = retries.increment(
  File "/home/bingxing2/ailab/wangkuncan/.conda/envs/setup/lib/python3.10/site-packages/urllib3/util/retry.py", line 519, in increment
    raise MaxRetryError(_pool, url, reason) from reason  # type: ignore[arg-type]
urllib3.exceptions.MaxRetryError: HTTPSConnectionPool(host='cdn-lfs-us-1.hf.co', port=443): Max retries exceeded with url: /repos/e4/5a/e45a14e07b22b4350ac8a49a28975e1003fc0cf125bd48861865ec4b58441dcf/1780a9502f56f592cb4d6262c8c76ca8ad36a86b0257e052c672d87f49707e80?response-content-disposition=inline%3B+filename*%3DUTF-8%27%27model-00002-of-000002.safetensors%3B+filename%3D%22model-00002-of-000002.safetensors%22%3B&Expires=1745309883&Policy=eyJTdGF0ZW1lbnQiOlt7IkNvbmRpdGlvbiI6eyJEYXRlTGVzc1RoYW4iOnsiQVdTOkVwb2NoVGltZSI6MTc0NTMwOTg4M319LCJSZXNvdXJjZSI6Imh0dHBzOi8vY2RuLWxmcy11cy0xLmhmLmNvL3JlcG9zL2U0LzVhL2U0NWExNGUwN2IyMmI0MzUwYWM4YTQ5YTI4OTc1ZTEwMDNmYzBjZjEyNWJkNDg4NjE4NjVlYzRiNTg0NDFkY2YvMTc4MGE5NTAyZjU2ZjU5MmNiNGQ2MjYyYzhjNzZjYThhZDM2YTg2YjAyNTdlMDUyYzY3MmQ4N2Y0OTcwN2U4MD9yZXNwb25zZS1jb250ZW50LWRpc3Bvc2l0aW9uPSoifV19&Signature=LtB5VXBbC3Mb1DQZ0phQJ95W2Wl8KeIXxGdwhBjnHx8c3Aj3yWJ~oJTSQZmdvot6DJdLq9ZX5kEU4n9KaABXr5NAbbc~MgRxrv4X5rprS2QlW6HcoQSRmuf6WNoELV2e9ebdKN4yWHq4IMJOObAI5Ksswxw4rS91TnUTVwkP7D3FXCKgEcDiwdvMWE3S7OGhOp09K5h5aa13~NN00cjAAhUECijkMIjHapYyjr8qE5NqkYJ6fnWk~KE2ahR9cqiPJs3uXPtwMf~5VMmtR2Z6Lu6JDETanmvtxdhP45Qq42jQH6-Wt-CpJUVzvgwTBS4mZckAW~Ij6SBiO1y3PyyyiA__&Key-Pair-Id=K24J24Z295AEI9 (Caused by ProxyError('Unable to connect to proxy', ReadTimeoutError("HTTPSConnectionPool(host='cdn-lfs-us-1.hf.co', port=443): Read timed out. (read timeout=10)")))

During handling of the above exception, another exception occurred:

Traceback (most recent call last):
  File "/home/bingxing2/ailab/wangkuncan/soft/l1/IntegratedCode.py", line 79, in <module>
    model = AutoModelForCausalLM.from_pretrained(
  File "/home/bingxing2/ailab/wangkuncan/.conda/envs/setup/lib/python3.10/site-packages/transformers/models/auto/auto_factory.py", line 564, in from_pretrained
    return model_class.from_pretrained(
  File "/home/bingxing2/ailab/wangkuncan/.conda/envs/setup/lib/python3.10/site-packages/transformers/modeling_utils.py", line 3671, in from_pretrained
    resolved_archive_file, sharded_metadata = get_checkpoint_shard_files(
  File "/home/bingxing2/ailab/wangkuncan/.conda/envs/setup/lib/python3.10/site-packages/transformers/utils/hub.py", line 1079, in get_checkpoint_shard_files
    cached_filename = cached_file(
  File "/home/bingxing2/ailab/wangkuncan/.conda/envs/setup/lib/python3.10/site-packages/transformers/utils/hub.py", line 402, in cached_file
    resolved_file = hf_hub_download(
  File "/home/bingxing2/ailab/wangkuncan/.local/lib/python3.10/site-packages/huggingface_hub/utils/_validators.py", line 114, in _inner_fn
    return fn(*args, **kwargs)
  File "/home/bingxing2/ailab/wangkuncan/.local/lib/python3.10/site-packages/huggingface_hub/file_download.py", line 961, in hf_hub_download
    return _hf_hub_download_to_cache_dir(
  File "/home/bingxing2/ailab/wangkuncan/.local/lib/python3.10/site-packages/huggingface_hub/file_download.py", line 1112, in _hf_hub_download_to_cache_dir
    _download_to_tmp_and_move(
  File "/home/bingxing2/ailab/wangkuncan/.local/lib/python3.10/site-packages/huggingface_hub/file_download.py", line 1675, in _download_to_tmp_and_move
    http_get(
  File "/home/bingxing2/ailab/wangkuncan/.local/lib/python3.10/site-packages/huggingface_hub/file_download.py", line 466, in http_get
    return http_get(
  File "/home/bingxing2/ailab/wangkuncan/.local/lib/python3.10/site-packages/huggingface_hub/file_download.py", line 376, in http_get
    r = _request_wrapper(
  File "/home/bingxing2/ailab/wangkuncan/.local/lib/python3.10/site-packages/huggingface_hub/file_download.py", line 308, in _request_wrapper
    response = get_session().request(method=method, url=url, **params)
  File "/home/bingxing2/ailab/wangkuncan/.local/lib/python3.10/site-packages/requests/sessions.py", line 589, in request
    resp = self.send(prep, **send_kwargs)
  File "/home/bingxing2/ailab/wangkuncan/.local/lib/python3.10/site-packages/requests/sessions.py", line 703, in send
    r = adapter.send(request, **kwargs)
  File "/home/bingxing2/ailab/wangkuncan/.local/lib/python3.10/site-packages/huggingface_hub/utils/_http.py", line 96, in send
    return super().send(request, *args, **kwargs)
  File "/home/bingxing2/ailab/wangkuncan/.local/lib/python3.10/site-packages/requests/adapters.py", line 694, in send
    raise ProxyError(e, request=request)
requests.exceptions.ProxyError: (MaxRetryError('HTTPSConnectionPool(host=\'cdn-lfs-us-1.hf.co\', port=443): Max retries exceeded with url: /repos/e4/5a/e45a14e07b22b4350ac8a49a28975e1003fc0cf125bd48861865ec4b58441dcf/1780a9502f56f592cb4d6262c8c76ca8ad36a86b0257e052c672d87f49707e80?response-content-disposition=inline%3B+filename*%3DUTF-8%27%27model-00002-of-000002.safetensors%3B+filename%3D%22model-00002-of-000002.safetensors%22%3B&Expires=1745309883&Policy=eyJTdGF0ZW1lbnQiOlt7IkNvbmRpdGlvbiI6eyJEYXRlTGVzc1RoYW4iOnsiQVdTOkVwb2NoVGltZSI6MTc0NTMwOTg4M319LCJSZXNvdXJjZSI6Imh0dHBzOi8vY2RuLWxmcy11cy0xLmhmLmNvL3JlcG9zL2U0LzVhL2U0NWExNGUwN2IyMmI0MzUwYWM4YTQ5YTI4OTc1ZTEwMDNmYzBjZjEyNWJkNDg4NjE4NjVlYzRiNTg0NDFkY2YvMTc4MGE5NTAyZjU2ZjU5MmNiNGQ2MjYyYzhjNzZjYThhZDM2YTg2YjAyNTdlMDUyYzY3MmQ4N2Y0OTcwN2U4MD9yZXNwb25zZS1jb250ZW50LWRpc3Bvc2l0aW9uPSoifV19&Signature=LtB5VXBbC3Mb1DQZ0phQJ95W2Wl8KeIXxGdwhBjnHx8c3Aj3yWJ~oJTSQZmdvot6DJdLq9ZX5kEU4n9KaABXr5NAbbc~MgRxrv4X5rprS2QlW6HcoQSRmuf6WNoELV2e9ebdKN4yWHq4IMJOObAI5Ksswxw4rS91TnUTVwkP7D3FXCKgEcDiwdvMWE3S7OGhOp09K5h5aa13~NN00cjAAhUECijkMIjHapYyjr8qE5NqkYJ6fnWk~KE2ahR9cqiPJs3uXPtwMf~5VMmtR2Z6Lu6JDETanmvtxdhP45Qq42jQH6-Wt-CpJUVzvgwTBS4mZckAW~Ij6SBiO1y3PyyyiA__&Key-Pair-Id=K24J24Z295AEI9 (Caused by ProxyError(\'Unable to connect to proxy\', ReadTimeoutError("HTTPSConnectionPool(host=\'cdn-lfs-us-1.hf.co\', port=443): Read timed out. (read timeout=10)")))'), '(Request ID: ba75de83-f166-4400-afa6-b8a5c2bd2a61)')
